<?xml version="1.0"?>
<robot xmlns:xacro="http://www.ros.org/wiki/xacro">

    <!-- links and joints go here -->

    <!-- The rest of the robot can be described from base_link, which is the centre point of the four driving wheels -->
    <link name="base_link">
    </link>

    <!-- chassis joint goes here. It connects chassis to base_link via fixed joint -->
    <joint name="chassis_joint" type="fixed">
        <parent link="base_link"/>
        <child link="chassis"/>
        <origin xyz="0 0 0"/>
    </joint>
    <!-- chassis description goes here. It describes the chassis of robocock which is a 54cm x 54cm x 150cm box -->
    <link name="chassis">
        <visual>
            <!-- by default, the origin is centred around the link origin, so offset it by half the height -->
            <origin xyz="0 0 0.75" rpy="0 0 0"/>
            <geometry>
                <box size="0.54 0.54 1.5"/>
            </geometry>
            <material name="white"/>
        </visual>
    </link>

    <!-- FRONT LEFT WHEEL AKA wheel_1 -->
    <joint name="wheel_1_joint" type="continuous">
        <parent link="base_link"/>
        <child link="wheel_1"/>
        <origin xyz="0 0.285 0" rpy="-${pi/2} 0 0"/>
        <axis xyz="0 0 1"/>
    </joint>

    <link name="wheel_1">
        <visual>
            <geometry>      
                <cylinder length="0.038" radius="0.05"/>
            </geometry>
            <material name="blue"/>
        </visual>
    </link>

</robot>